## 2020. 02. 25.

### 코틀린 - 코루틴 취소와 타임아웃(4)

#### 타임아웃

코루틴 실행을 취소할 만한 가장 확실한 이유는 실행 시간이 타임아웃을 초과했기 때문일 것이다. 이를 위해 수동으로 해당하는 [`Job`][kt-job]의 참조를 추적하면서 일정 시간 이후에 이를 취소하는 별도의 코루틴을 실행할 수도 있다. 이를 수행하는 [`withTimeout`][kt-with-timeout]함수가 준비돼 있다. 다음 예시를 보자:

```kotlin
withTimeout(1300L) {
    repeat(1000) { i ->
        println("I'm sleeping $i ...")
        delay(500L)
    }
}
```

다음과 같이 출력된다:

```
I'm sleeping 0 ...
I'm sleeping 1 ...
I'm sleeping 2 ...
Exception in thread "main" kotlinx.coroutines.TimeoutCancellationException: Timed out waiting for 1300 ms
```

`TimeoutCancellationException`이 바로 [`withTimeout`][kt-with-timeout]이 던진 [`CancellationException`][kt-cancellation-exception]의 서브클래스다. 콘솔에 스택 트레이스가 출력되지 않은 것을 볼 수 있는데, 이는 취소된 코루틴 내에서 `CancellationException`이 코루틴을 정상적으로 완료할 수 있는 사유이기 때문이다. 하지만 이 예시에서는 `withTimeout`을 `main`의 바로 안에서 사용했다.

취소는 그저 예외이기 때문에 모든 리소스들은 보통의 방식으로 닫힌다. 타임아웃에만 따로 별도의 동작이 필요한 경우 타임아웃이 있는 코드를 `try { ... } catch (e: TimeoutCancellationException) { ... }` 블럭으로 감쌀 수도 있다. 혹은 [`withTimeoutOrNull`][kt-with-timeout-or-null] 함수를 사용할 수도 있다. 이 함수는 [`withTimeout`][kt-with-timeout]과 비슷하지만 타임아웃이 발생하면 예외를 던지는 대신 `null`을 반환한다:

```kotlin
val result = withTimeoutOrNull(1300L) {
    repeat(1000) { i ->
        println("I'm sleeping $i ...")
        delay(500L)
    }
    "Done" // will get cancelled before it produces this result
}
println("Result is $result")
```

코드를 실행하면 더이상 예외가 발생하지 않는다:

```
I'm sleeping 0 ...
I'm sleeping 1 ...
I'm sleeping 2 ...
Result is null
```



[kt-job]: https://kotlin.github.io/kotlinx.coroutines/kotlinx-coroutines-core/kotlinx.coroutines/-job/index.html
[kt-with-timeout]: https://kotlin.github.io/kotlinx.coroutines/kotlinx-coroutines-core/kotlinx.coroutines/with-timeout.html
[kt-cancellation-exception]: https://kotlin.github.io/kotlinx.coroutines/kotlinx-coroutines-core/kotlinx.coroutines/-cancellation-exception/index.html
[kt-with-timeout-or-null]: https://kotlin.github.io/kotlinx.coroutines/kotlinx-coroutines-core/kotlinx.coroutines/with-timeout-or-null.html