# 2025. 02. 20.

## Reactor 3 Reference Guide

### Reactor Core 기능

#### 오류 처리

##### 1. 오류 처리 연산자

try-catch 블럭으로 예외를 처리하는 몇 가지 방법에는 익숙할 것이다. 대표적으로 다음과 같은 것들이 있다:

* 예외를 잡고 정적 기본값을 반환한다.
* 예외를 잡고 폴백(fallback) 메서드로 대체 경로를 실행한다.
* 예외를 잡고 폴백 값을 동적으로 계산한다.
* 예외를 잡아 `BusinessException`으로 감싼 뒤 다시 던진다.
* 에외를 잡아 오류에 특화된 메시지를 로그로 남기고 다시 던진다.
* `finally` 블럭을 사용해 리소스를 정리하거나 Java 7의 "try-with-resource" 구문을 사용한다.

Reactor에서는 오류 처리 연산자의 관점에서 이들이 모두 동등하다. 이 연산자들을 살펴보기 전에 먼저 리액티브 체인과 try-catch 블럭 사이의 유사점을 알아보자.

구독할 때 체인 끝의 `onError` 콜백은 `catch` 블럭과 유사하다. 다음 예제처럼 `Exception`이 던져지면 실행을 catch로 건너뛴다:

```java
Flux<String> s = Flux.range(1, 10)
    .map(v -> doSomethingDangerous(v)) // 1. 예외를 던질 수 있는 변환이 수행된다.
    .map(v -> doSecondTransform(v)); // 2. 잘 동작하면 두 번째 변환이 수행된다.
s.subscribe(value -> System.out.println("RECEIVED " + value),  // 3. 성공적으로 변환된 각 값이 출력된다.
            error -> System.err.println("CAUGHT " + error) // 4. 오류가 발생하면 시퀀스를 종료하고 오류 메시지가 표시된다.
);
```

앞의 예제는 다음 try-catch 블럭과 개념적으로 비슷하다:

```java
try {
    for (int i = 1; i < 11; i++) {
        String v1 = doSomethingDangerous(i); // 1. 여기서 예외가 던져지면
        String v2 = doSecondTransform(v1); // 2. 루프의 나머지는 건너뛴다.
        System.out.println("RECEIVED " + v2);
    }
} catch (Throwable t) {
    System.err.println("CAUGHT " + t); // 3. 그리고 실행은 곧바로 이곳으로 향한다.
}
```

이제 닮은 점을 알아봤으니 서로 다른 오류 처리 사례와 이에 동등한 연산자들을 살펴보자.

