# 2025. 03. 03.

## Reactor 3 Reference Guide

### Reactor Core 기능

#### 오류 처리

##### 2. 연산자나 함수로 예외 처리

일반적으로, 모든 연산자들 자체는 잠재적으로 예외를 유발할 수 있거나 그와 비슷하게 실패할 수 있는 사용자 정의 콜백을 호출하는 코드를 포함하므로 이들 모두 어떤 형태로든 오류 처리를 갖는다.

경험상, 비검사 예외(unchecked exception)는 항상 `onError`를 통해 전파된다. 예를 들어, `map` 함수 내에서 `RuntimeException`을 던지면 `onError` 이벤트로 변환된다:

```java
Flux.just("foo")
    .map(s -> { throw new IllegalArgumentException(s); })
    .subscribe(v -> System.out.println("GOT VALUE"),
               e -> System.out.println("ERROR: " + e));
```

출력은 다음과 같다:

```
ERROR: java.lang.IllegalArgumentException: foo
```

> [!TIP]
>
> [훅][reactor-core-adv-feature-hook]을 사용해 `Exception`이 `onError`에 전달되기 전에 조정할 수 있다.

하지만 Reactor는 (`OutOfMemoryError`와 같이)항상 치명적인 것으로 간주하는 예외 집합을 정의한다. `Exceptions.throwIfFatal` 메서드를 참고하라. 이 오류들은 Reactor가 계속 동작할 수 없어 전파하는 대신 던짐을 의미한다.

> [!NOTE]
>
> 더블 `onError`나 `onComplete` 조건으로 이어질 수 있는 동시성 경합으로 인해 내부적으로 (특히 구독과 요청 단계에서)비검사 예외도 전파될 수 없는 경우가 있다. 이러한 경합이 발생하면 전파될 수 없는 오류는 "버려진다"(dropped). 커스터마이즈 가능한 훅을 사용해 이러한 상황도 여전히 처리할 수 있다. [드로핑 훅][reactor-core-adv-feature-hook]을 참고하라.

이렇게 질문할 수도 있다: "검사된 예외(checked exception)에 대해서는 어떤가?"

예를 들어 예외를 `throws`하는 메서드를 호출해야 한다면 이러한 예외들은 여전히 `try-catch-` 블럭에서 처리해야 한다. 하지만 몇 가지 선택지가 있다:

1. 예외를 잡아 복구한다. 시퀀스는 계속된다.
2. 예외를 잡고 *비검사* 예외로 감싼 다음 던진다(시퀀스를 인터럽트한다). `Exceptions` 유팉리티 클래스가 도움이 될 수 있다.
3. (예를 들어 `flatMap` 내부에서처럼) `Flux`를 반환해야 한다면, `return Flux.error(checkedException)`처럼 예외를 오류를 만들어내는 `Flux`로 감싼다. (시퀀스도 종료시킨다)

Reactor는 검사 예외일 때만 감싸는 `Exceptions` 유틸리티 클래스를 갖고 있다:

* 필요한 경우 `Exceptions.propagate` 메서드를 사용해 예외를 감싼다. 또한 `throwIfFatal`을 먼저 호출하고 `RuntimeException`을 감싸지 않는다.
* `Exceptions.unwrap` 메서드를 사용해 감싸지지 않은 원본 예외를 얻는다(Reactor 특화 예외 계층의 루트로 되돌아간다).

다음 예시는 `IOException`을 던질 수 있는 변환을 사용하는 `map`이다:

```java
public String convert(int i) throws IOException {
    if (i > 3) {
        throw new IOException("boom " + i);
    }
    return "OK " + i;
}
```

이제 이 메서드를 `map`에서 사용하려 한다고 하자. 이제 명시적으로 예외를 잡아야 하며 `map` 함수는 이를 다시 던질 수 없다. 따라서 `map`의 `onError` 메서드로 `RuntimeException`으로 전파할 수 있다:

```java
Flux<String> converted = Flux
    .range(1, 10)
    .map(i -> {
        try { return convert(i); }
        catch (IOException e) { throw Exceptions.propagate(e); }
    });
```

그 뒤, (UI에서와 같이)앞선 `Flux`에 대한 구독이 오류로 반응하면 IOException에 대해 특별히 해야 할 작업이 있는 경우 다음 예시처럼 원본 예외로 되돌릴 수 있다:

```java
converted.subscribe(
    v -> System.out.println("RECEIVED: " + v),
    e -> {
        if (Exceptions.unwrap(e) instanceof IOException) {
            System.out.println("Something bad happened with I/O");
        } else {
            System.out.println("Something bad happened");
        }
    }
);
```



[reactor-core-adv-feature-hook]: https://projectreactor.io/docs/core/release/reference/advancedFeatures/hooks.html#hooks-internal