## 2020. 03. 26.

### 코틀린 - 비동기 플로우(12)

#### 플로우 완료

플로우 수집이 완료되면 수행할 동작이 필요할 수 있다. 이미 알고 있을지도 모르겠지만 명령형 또는 선언형의 두 가지 방법이 있다.

##### 명령적 finally 블럭

`try/catch` 외에, 컬렉터는 `collect`가 완료된 뒤 코드를 실행하기 위해 `finally` 블럭도 사용할 수 있다.

```kotlin
fun foo(): Flow<Int> = (1..3).asFlow()

fun main() = runBlocking<Unit> {
    try {
        foo().collect { value -> println(value) }
    } finally {
        println("Done")
    }
}            
```

이 코드는 `foo()` 플로우가 생성한 세 개의 숫자와 마지막에 "Done" 문자열을 출력한다:

```
1
2
3
Done
```

##### 선언적 처리

선언적인 접근 방식으로, 플로우는 자신이 성공적으로 수집되면 호출되는 [`onCompletion`][kt-flow-on-completion] 중간 연산자를 가지고 있다.

앞의 예시는 [`onCompletion`][kt-flow-on-completion] 연산자를 이용해 다음과 같이 재작성할 수 있으며, 출력은 동일하다:

```kotlin
foo()
    .onCompletion { println("Done") }
    .collect { value -> println(value) }
```

[`onCompletion`][kt-flow-on-completion]의 핵심은 플로우가 정상적으로 혹은 예외로 인해 완료됐는지 판별하기 위해 nullable한 `Throwable` 파라미터를 람다의 인자로 갖는다는 것이다. 다음 예시는 `foo()` 플로우가 숫자 1을 방출한 뒤 예외를 던진다:

```kotlin
fun foo(): Flow<Int> = flow {
    emit(1)
    throw RuntimeException()
}

fun main() = runBlocking<Unit> {
    foo()
        .onCompletion { cause -> if (cause != null) println("Flow completed exceptionally") }
        .catch { cause -> println("Caught exception") }
        .collect { value -> println(value) }
}            
```

기대했던 대로, 다음과 같이 출력된다:

```
1
Flow completed exceptionally
Caught exception
```

#### 명령적 vs 선언적

명령형 방식과 선언형 방식으로 플로우를 어떻게 수집하고 완료와 예외를 어떻게 처리하는 지 알아봤다. 여기서 자연스러운 질문은 어느 접근 방식이 더 선호되고, 그 이유는 무엇인가이다. 여기서는 라이브러리로서 특정 접근 방식을 지지하지는 않는다. 두 방식 모두 유효하고 코드 스타일에 따라 선택하는 것이 좋다.



[kt-flow-on-completion]: https://kotlin.github.io/kotlinx.coroutines/kotlinx-coroutines-core/kotlinx.coroutines.flow/on-completion.html