## 2020. 03. 24.

### 코틀린 - 비동기 플로우(10)

#### 플로우 예외

이미터(emitter) 또는 연산자 내의 코드가 예외를 던지면 플로우 수집이 예외로 끝날 수 있다. 이러한 예외를 처리하는 몇 가지 방법들이 있는데, 이에 대해 알아보자.

##### 컬렉터 try-catch

컬렉터는 코틀린의 [`try/catch`][kt-exception] 블럭을 사용할 수 있다:

```kotlin
fun foo(): Flow<Int> = flow {
    for (i in 1..3) {
        println("Emitting $i")
        emit(i) // emit next value
    }
}

fun main() = runBlocking<Unit> {
    try {
        foo().collect { value ->         
            println(value)
            check(value <= 1) { "Collected $value" }
        }
    } catch (e: Throwable) {
        println("Caught $e")
    } 
}            
```

이 코드는 [`collect`][kt-flow-collect] 최종 연산자에서 성공적으로 예외를 잡는다. 출력에서 볼 수 있듯이, 그 이후에 다른 값은 방출되지 않는다:

```
Emitting 1
1
Emitting 2
2
Caught java.lang.IllegalStateException: Collected 2
```

##### 잡히는 모든 것

이전 예시는 이미터 혹은 중간/최종 연산자에서 발생한 예외를 잡는다. 예를 들어, 방출된 값을 문자열로 바꾸지만 예외가 발생하도록 코드를 수정해보자:

```kotlin
fun foo(): Flow<String> = 
    flow {
        for (i in 1..3) {
            println("Emitting $i")
            emit(i) // emit next value
        }
    }
    .map { value ->
        check(value <= 1) { "Crashed on $value" }                 
        "string $value"
    }

fun main() = runBlocking<Unit> {
    try {
        foo().collect { value -> println(value) }
    } catch (e: Throwable) {
        println("Caught $e")
    } 
}            
```

여전히 예외는 잡히고 수집은 멈춘다:

```
Emitting 1
string 1
Emitting 2
Caught java.lang.IllegalStateException: Crashed on 2
```

 

[kt-exception]: https://kotlinlang.org/docs/reference/exceptions.html
[kt-flow-collect]: https://kotlin.github.io/kotlinx.coroutines/kotlinx-coroutines-core/kotlinx.coroutines.flow/collect.html