## 2020. 04. 11.

### 코틀린 - 예외 처리와 관리(4)

#### 예외 집계(aggregation)

만일 코루틴의 여러 자식들이 예외를 던진다면 어떨까? 일반적인 규칙은 "첫 번째 예외가 이긴다"이므로 먼저 던져진 예외가 핸들러에 노출된다. 하지만 이는 예외 손실을 유발할 수도 있다. 예를 들어 코루틴이 자신의 `finally` 블럭에서 예외를 던질 수도 있다. 이러한 추가적인 예외들은 억제(suppress)된다.

> 한 가지 해법은 각 예외를 별도로 보고하는 것인데, 그러려면 비일관적으로 동작하는 것을 막기 위해 [`Deferred.await`][kt-coroutine-deferred-await]이 동일한 메커니즘을 가져야 하고, 이는 (자기 자식에게 위임한 동작이든 아니든)코루틴의 상세 구현이 예외 핸들러를 누락시킬 수도 있다.

```kotlin
import kotlinx.coroutines.*
import java.io.*

fun main() = runBlocking {
    val handler = CoroutineExceptionHandler { _, exception ->
        println("Caught $exception with suppressed ${exception.suppressed.contentToString()}")
    }
    val job = GlobalScope.launch(handler) {
        launch {
            try {
                delay(Long.MAX_VALUE)
            } finally {
                throw ArithmeticException()
            }
        }
        launch {
            delay(100)
            throw IOException()
        }
        delay(Long.MAX_VALUE)
    }
    job.join()  
}
```

> 이 코드는 억제된 예외(supprssed exceptions)를 지원하는 JDK7+ 에서만 제대로 동작할 것이다.

이 코드의 출력은 다음과 같다:

```
Caught java.io.IOException with suppressed [java.lang.ArithmeticException]
```

> 참고로, 이 메커니즘은 현재 Java 버전 1.7+에서만 동작한다. JS와 Native에 대해서는 추후에 지원될 예정이다.

취소 예외는 투명하며 기본적으로 감싸지 않는다:

```kotlin
val handler = CoroutineExceptionHandler { _, exception ->
    println("Caught original $exception")
}
val job = GlobalScope.launch(handler) {
    val inner = launch {
        launch {
            launch {
                throw IOException()
            }
        }
    }
    try {
        inner.join()
    } catch (e: CancellationException) {
        println("Rethrowing CancellationException with original cause")
        throw e
    }
}
job.join()
```

이 코드의 출력은:

```
Rethrowing CancellationException with original cause
Caught original java.io.IOException
```



[kt-coroutine-deferred-await]: https://kotlin.github.io/kotlinx.coroutines/kotlinx-coroutines-core/kotlinx.coroutines/-deferred/await.html