## 2020. 04. 10.

### 코틀린 - 예외 처리와 관리(3)

#### 취소와 예외

취소는 예외와 단단히 묶여있다. 코루틴은 취소에 내부적으로 `CancellationException`을 사용한다. 이러한 예외들은 모든 핸들러들이 무시하며, 따라서 `catch` 블럭으로 얻을 수 있는 추가적인 디버그 정보의 출처로만 사용해야 한다. 코루틴을 [`Job.cancel`][kt-couroutine-job-cancel]로 취소하면 자신은 종료하지만 부모를 취소하지는 않는다.

```kotlin
val job = launch {
    val child = launch {
        try {
            delay(Long.MAX_VALUE)
        } finally {
            println("Child is cancelled")
        }
    }
    yield()
    println("Cancelling child")
    child.cancel()
    child.join()
    yield()
    println("Parent is not cancelled")
}
job.join()
```

이 코드의 출력은:

```
Cancelling child
Child is cancelled
Parent is not cancelled
```

만일 코루틴이 `CancellationException` 이외의 예외를 마주치면, 자신의 부모를 해당 예외로 취소한다. 이 동작은 재정의할 수 없으며, 이는 [`CoroutineExceptionHandler`][kt-coroutine-exception-handler]의 구현에 의존하지 않는 [구조화된 동시성][kt-coroutine-structured-concurrency]을 위한 코루틴 계층 구조를 제공하는 데 사용한다. 원본 예외는 모든 자식이 종료되면 부모에 의해 처리된다.

> 이는 또한 이 예시에서 [`CoroutineExceptionHandler`][kt-coroutine-exception-handler]를 항상 [`GlobalScope`][kt-coroutine-global-scope]에 생성된 코루틴에 두는 이유이기도 하다. 예외 핸들러를 메인 [`runBlocking`][kt-coroutine-run-blocking]의 스코프에 실행된 코루틴에 두는 것은 말이 안된다. 메인 코루틴은 자신의 자식이 완료되면 핸들러를 둔다고 하더라도 항상 취소될 것이기 때문이다.

```kotlin
val handler = CoroutineExceptionHandler { _, exception -> 
    println("Caught $exception") 
}
val job = GlobalScope.launch(handler) {
    launch { // the first child
        try {
            delay(Long.MAX_VALUE)
        } finally {
            withContext(NonCancellable) {
                println("Children are cancelled, but exception is not handled until all children terminate")
                delay(100)
                println("The first child finished its non cancellable block")
            }
        }
    }
    launch { // the second child
        delay(10)
        println("Second child throws an exception")
        throw ArithmeticException()
    }
}
job.join()
```

이 코드의 출력은 다음과 같다:

```
Second child throws an exception
Children are cancelled, but exception is not handled until all children terminate
The first child finished its non cancellable block
Caught java.lang.ArithmeticException
```



[kt-couroutine-job-cancel]: https://kotlin.github.io/kotlinx.coroutines/kotlinx-coroutines-core/kotlinx.coroutines/-job/cancel.html
[kt-coroutine-exception-handler]: https://kotlin.github.io/kotlinx.coroutines/kotlinx-coroutines-core/kotlinx.coroutines/-coroutine-exception-handler/index.html
[kt-coroutine-structured-concurrency]: https://github.com/Kotlin/kotlinx.coroutines/blob/master/docs/composing-suspending-functions.md#structured-concurrency-with-async
[kt-coroutine-global-scope]: https://kotlin.github.io/kotlinx.coroutines/kotlinx-coroutines-core/kotlinx.coroutines/-global-scope/index.html
[kt-coroutine-run-blocking]: https://kotlin.github.io/kotlinx.coroutines/kotlinx-coroutines-core/kotlinx.coroutines/run-blocking.html